Workbook

Sheet Summary
A1: COST ESTIMATE REVIEW - Payment Resolution Agentic Workflow (EPIC 3 email + EPIC 4 FootPrints)
A3: # | B3: FINDING | C3: MONTHLY IMPACT | D3: WHAT TO DO
A4: 1 | B4: Agentic consumption is under-modelled by roughly an order of magnitude | C4: ='Consumption Model'!B53-'Consumption Model'!B54 -> 1701.63 | D4: The model line assumes ~2 inference calls per agent session (54,000 requests / 27,000 sessions), a flat 4,000 input tokens per call, and no multi-invoice fan-out. A ReAct loop with 8 tool calls needs ~9 inference calls, and the context grows on every turn because the system prompt and 15 tool schemas are resent each time. Rebuild from the Consumption Model sheet.
A5: 2 | B5: The model is never named, and the implied choice is the most expensive one | C5: structural | D5: Reverse-engineering the configuration ($5/$25 per million against 216M in / 43.2M out = exactly $2,160) shows the estimate is priced on Claude Opus 4.8. Nothing in the requirements calls for a frontier model to run a binary intent gate. Splitting the two agents by capability is the single cheapest correction available.
A6: 3 | B6: Bedrock Guardrails is mandated but entirely absent | C6: ='Consumption Model'!B59 -> 60.642 | D6: Item #2 on the AWS service list is 'Yes' for both epics and both architecture versions. More important than the omission is the placement decision: screening every agent turn instead of just the supplier boundary costs 10-20x more and adds no control where it matters.
A7: 4 | B7: NAT Gateway priced at zero with five gateways configured | C7: =70 -> 70 | D7: The largest arithmetic error in the sheet. NAT gateways bill hourly plus per-GB regardless of traffic. Five gateways would be roughly $164/month before data processing. Confirm the real AZ topology - two is the more likely design.
A8: 5 | B8: PrivateLink interface endpoints missing entirely | C8: =263 -> 263 | D8: The architecture specifies VPC endpoints and controlled egress, and the service list confirms them at #27. Twelve endpoints across three AZs exceeds every line in the current estimate except model inference and CloudWatch.
A9: 6 | B9: The cost estimate and the service list describe two different architectures | C9: structural | D9: The estimate prices the AgentCore managed path (Runtime, Gateway, Memory, Identity, Code Interpreter). The service list marks ECS Cluster, Fargate for MCP, and Fargate for a custom orchestrator as 'Yes' for both epics. These are alternatives, not complements. Resolve before any figure is trustworthy - it changes the compute model entirely.
A10: 7 | B10: Four lines should be removed outright | C10: =-64.77 -> -64.77 | D10: AgentCore Identity (free via Runtime/Gateway), AgentCore Code Interpreter (nothing executes generated code), DynamoDB (not in the architecture; Aurora is the authoritative store), and Gateway Load Balancer (not on the service list; no inspection appliance in the design).
A11: 8 | B11: CloudWatch contains a mis-selection and is understated | C11: =64.32 -> 64.32 | D11: The configuration includes mobile OTEL events and a mobile sampling rate. There is no mobile application in this architecture. Separately, 1 GB per log category cannot cover 30 Lambdas, agent traces and VPC flow logs. AgentCore Observability also bills through CloudWatch, so that $0.85 line double-counts a cost that belongs here.
A12: 9 | B12: Aurora sized at the floor with no HA | C12: =163.83 -> 163.83 | D12: 1 ACU, single instance, 10 GB. This is the authoritative case, evidence and audit store for roughly 324,000 cases in year one. Model 2-4 ACU, a second instance, and a storage growth curve.
A13: 10 | B13: No volume basis exists anywhere | C13: structural | D13: The 27,000 sessions, 200,000 Lambda requests, 10,000 Textract pages and 26,000 workflows are not traceable to any stated email or ticket volume. Stage 1 decision 6 deferred NFRs, which is exactly where volume would have been captured. Every figure in both sheets rests on this gap.
B15: BOTTOM LINE
B16: Current estimate, 12 months | C16: =32669.16 -> 32669.16
B17: Reviewed BASE case, 12 months | C17: =Scenarios!C9 -> 66872.424
B18: Reviewed range, 12 months (low to high) | C18: =TEXT(Scenarios!B9,"$#,##0")&" to "&TEXT(Scenarios!D9,"$#,##0") -> $36,473 to $152,740
B20: Rate verification: AgentCore Runtime $0.0895/vCPU-hour and $0.00945/GB-hour, and the Bedrock Claude rates used here, were checked against published pricing in September 2026. AWS rates change; re-verify in the AWS Pricing Calculator before this goes to the client. Indicative figures for services with no usage configuration are order-of-magnitude placeholders intended to show materiality, not quotes.

Sheet Consumption Model
A1: AGENTIC CONSUMPTION MODEL - two agents, session and token build-up
A3: BLUE cells are inputs you can change. Black cells are formulas. Every downstream sheet recalculates from here.
A5: 1. VOLUME DRIVERS | F5: BASIS / WHY THIS MATTERS
A6: Inbound supplier emails per month (EPIC 3) | B6: 9000 | F6: NOT DOCUMENTED ANYWHERE. Stage 1 decision 6 deferred all NFRs, so no volume baseline exists. This figure is reverse-engineered to reconcile with the 27,000 sessions in the current estimate.
A7: FootPrints PO-mismatch tickets per month (EPIC 4) | B7: 3000 | F7: NOT DOCUMENTED. FR16 states this queue is already classified, so these tickets skip the classification agent.
A8: Share of emails in scope after classification | B8: 0.8 | F8: FR7 intent gate. Out-of-scope mail is discarded and consumes one classification call only.
A9: Investigation subjects per case (multi-invoice fan-out) | B9: 1.5 | F9: One email can name several invoices. Stage 4 fan-out point. If each subject is its own agent session this multiplies every agent cost line. The current estimate has no fan-out factor at all.
A11: 2. SESSION MODEL - the two agents have different cost shapes
B12: Sessions / month | F12: BASIS
A13: Email Classification Agent sessions | B13: =B6 -> 9000 | F13: One per inbound email. Single model call, small context, no tool calls. FootPrints tickets do NOT run this agent (FR16).
A14: Payment Investigation Agent sessions | B14: =(B6*B8*B9)+(B7*B9) -> 15300 | F14: Multi-turn ReAct loop with tool calls and accumulating context. This is where virtually all model spend sits.
A15: TOTAL agent sessions per month | B15: =B13+B14 -> 24300 | F15: Compare with the 27,000 used in every AgentCore line of the current estimate.
A16: Sessions assumed in the current estimate | B16: 27000 | F16: The current estimate applies one blended 27,000 to Runtime, Gateway, Identity, Memory and Code Interpreter. Blending a 15-second classification call with a 4-minute investigation loop distorts both.
A18: 3. TOKEN BUILD-UP PER SESSION - the line the current estimate gets most wrong
A19: Tool invocations per investigation session | B19: 8 | F19: Taken from the current estimate's own AgentCore Gateway configuration.
A20: Model calls per investigation session | B20: =B19+1 -> 9 | F20: Equals tool invocations + 1. Each tool result must be returned to the model to decide the next step. The current estimate implies only 2 model calls per session (54,000 requests / 27,000 sessions).
A21: System prompt + 15 tool schemas (tokens) | B21: 5000 | F21: RESENT ON EVERY CALL. With 15 tools defined, schemas alone are a large fixed cost per turn. This is the mechanism behind agentic token amplification.
A22: Case context tokens | B22: 1500 | F22: Case, subject, thread and prior-evidence summary carried into the loop.
A23: Evidence tokens added per turn | B23: 1200 | F23: Each tool result (Ariba invoice, IR object, PO lines, receipt lines) accumulates in the context window.
A24: Output tokens per tool-selection turn | B24: 400 | F24: Short structured tool-call output.
A25: Output tokens on the final drafting turn | B25: 1200 | F25: Evidence-grounded draft plus claim map (FR13).
A26: Classification input tokens per call | B26: 3500 | F26: Subject, body, prior thread, extracted attachment text.
A27: Classification output tokens per call | B27: 250 | F27: Structured classification verdict only.
A29: 4. MONTHLY TOKEN VOLUME
A30: Average input tokens per investigation model call | B30: =B21+B22+(B23*(B20-1)/2) -> 11300 | F30: Fixed prompt plus half the accumulated evidence, averaged across the loop. Turn 1 is smaller, the final turn is much larger. The current estimate uses a flat 4,000 for every call.
A31: Investigation input tokens per month | B31: =B14*B20*B30 -> 1556010000
A32: Investigation output tokens per month | B32: =B14*(((B20-1)*B24)+B25) -> 67320000
A33: Classification input tokens per month | B33: =B13*B26 -> 31500000
A34: Classification output tokens per month | B34: =B13*B27 -> 2250000
A35: TOTAL input tokens per month | B35: =B31+B33 -> 1587510000
A36: TOTAL output tokens per month | B36: =B32+B34 -> 69570000
A37: Input tokens implied by the CURRENT estimate | B37: 216000000 | F37: 3 requests/min x 60 x 10 hours x 30 days = 54,000 requests, at 4,000 input tokens each.
A38: Output tokens implied by the CURRENT estimate | B38: 43200000
A39: UNDERSTATEMENT FACTOR on input tokens | B39: =B35/B37 -> 7.3495833 | F39: Independent sources put single-agent token amplification at roughly 4x a plain chat call, before fan-out. The gap here comes from three compounding factors: too few model calls per session, no growth in context across turns, and no fan-out.
A41: 5. MODEL RATE CARD (Bedrock on-demand, USD per 1M tokens, verified Sept 2026)
A42: Model | B42: Input $/1M | C42: Output $/1M | F42: NOTE
A43: Claude Opus 4.8 | B43: 5 | C43: 25 | F43: WHAT THE CURRENT ESTIMATE USES. 216M x $5 + 43.2M x $25 = $2,160 exactly. The model choice is nowhere stated in the sheet.
A44: Claude Sonnet 5 | B44: 3 | C44: 15 | F44: Standard rate. The Global launch rate of $2/$10 expired 31 Aug 2026.
A45: Claude Haiku 4.5 | B45: 1 | C45: 5 | F45: Appropriate for the classification agent, which is a structured routing decision, not reasoning.
A47: 6. MONTHLY MODEL SPEND BY STRATEGY
...

Sheet Line Review
A1: LINE-BY-LINE REVIEW OF THE CURRENT ESTIMATE (27 line items, $2,722.43 / month)
A3: Service line | B3: Current monthly $ | C3: Finding | D3: Severity | E3: Corrected monthly $ | F3: Delta $ | G3: Basis / action
A4: AgentCore Runtime | B4: 72.95 | C4: Arithmetic is correct at $0.0895/vCPU-hr and $0.00945/GB-hr. But 120s average session and a single blended 27,000 sessions mix a 15-second classification call with a multi-turn investigation loop. | D4: MEDIUM | E4: 110 | F4: =E4-B4 -> 37.05 | G4: Split the two agents. Model the investigation agent at ~240s with 2 vCPU / 2 GB. Consider running classification as a direct Bedrock Converse call from Lambda, which removes it from Runtime billing entirely.
A5: AgentCore Gateway | B5: 3.11 | C5: Charged on all 27,000 sessions, but classification sessions make no tool calls. Slightly overstated. 15 tools defined vs 17 data pulls in the Stage 9 design. | D5: LOW | E5: 3 | F5: =E5-B5 -> -0.11 | G5: Reconcile the tool count with the pull register. Immaterial either way.
A6: AgentCore Identity | B6: 4.32 | C6: AWS states Identity carries no additional charge when used through Runtime or Gateway, which is exactly how this architecture uses it. | D6: REMOVE | E6: 0 | F6: =E6-B6 -> -4.32 | G6: Delete the line unless a non-Runtime, non-Gateway call path exists. Verify on the AgentCore pricing page.
A7: AgentCore Code Interpreter | B7: 1.22 | C7: Priced for all 27,000 sessions at 180s. Nothing in the architecture executes generated code - the deterministic comparison engine is Lambda-based. | D7: REMOVE | E7: 0 | F7: =E7-B7 -> -1.22 | G7: Delete unless a concrete use case exists. Its presence suggests the estimate was built by filling the calculator rather than from the architecture.
A8: AgentCore Memory | B8: 37.13 | C8: Short-term only, applied to all 27,000 sessions. Only investigation sessions need working context. No long-term memory strategy is priced. | D8: LOW | E8: 28 | F8: =E8-B8 -> -9.13 | G8: Confirm that case continuity lives in Aurora (it does per the container diagram), so only short-term memory is needed. Each long-term strategy that extracts on every session adds write, storage and retrieval cost.
A9: AgentCore Observability | B9: 0.85 | C9: AgentCore Observability bills through CloudWatch, not a standalone rate. 1 GB of logs and 1 GB of spans for 27,000 multi-turn agent sessions is far too low. | D9: HIGH | E9: 0 | F9: =E9-B9 -> -0.85 | G9: Remove this line and fold realistic agent telemetry into the CloudWatch line. Expect 20-80 GB/month of traces and spans at this session volume.
A10: Anthropic (Bedrock model inference) | B10: 2160 | C10: THE DOMINANT LINE - 79% of the current total. Reverse-engineering the config gives 54,000 requests at 4,000 in / 800 out, priced at $5/$25, i.e. Claude Opus 4.8. The model is never named in the sheet. Three compounding understatements: ~2 model calls per session instead of ~9, flat context instead of accumulating, and no fan-out factor. | D10: CRITICAL | E10: ='Consumption Model'!B53 -> 3861.63 | F10: =E10-B10 -> 1701.63 | G10: See the Consumption Model sheet. Corrected figure links from there.
A11: AWS Lambda | B11: 0.03 | C11: No memory size or duration is configured, and 200,000 requests is below the real figure - tool-container Lambdas alone are ~8 per investigation session. | D11: LOW | E11: 30 | F11: =E11-B11 -> 29.97 | G11: Re-model at ~400,000 invocations, 1 GB, 2-4s average (Ariba and S/4 calls are slow). Still small in absolute terms.
A12: Aurora PostgreSQL Serverless | B12: 56.17 | C12: 1 ACU is the floor and will not hold for case writes, evidence persistence, audit and reviewer-queue reads. No HA instance is priced. 10 GB storage is far too small - at this volume the estimate implies ~324,000 cases in year one, each with an evidence chain and Ariba snapshots. | D12: HIGH | E12: 220 | F12: =E12-B12 -> 163.83 | G12: Model 2-4 ACU average with a second instance for HA, and a storage growth curve. This is the authoritative case, evidence and audit store per the container diagram.
A13: Amazon EventBridge | B13: 0.09 | C13: Reasonable. | D13: OK | E13: 0.09 | F13: =E13-B13 -> 0 | G13: No change.
A14: Amazon SQS | B14: 0.5 | C14: Reasonable. | D14: OK | E14: 0.5 | F14: =E14-B14 -> 0 | G14: No change.
A15: DynamoDB on-demand | B15: 37.32 | C15: Not in the AWS service requirement list and not in the container diagram, which names Aurora PostgreSQL as the authoritative store. Only storage is configured - no request volume. | D15: REMOVE | E15: 0 | F15: =E15-B15 -> -37.32 | G15: Remove, or document what it stores that Aurora does not. As configured it is a storage-only charge for a table nothing in the architecture writes to.
A16: S3 Standard | B16: 2.59 | C16: 100 GB and 50k PUT / 100k GET. Plausible for month one, but no lifecycle policy is modelled and the landing / clean / quarantine pattern means ~3 PUTs per attachment. | D16: LOW | E16: 4 | F16: =E16-B16 -> 1.41 | G16: Add a lifecycle policy and a 12-month growth curve for the audit prefix.
A17: Data Transfer | B17: 0 | C17: Configured as 10 TB inbound from internet and zero outbound. Inbound is free so $0 is technically right, but 10 TB inbound is not a real figure for this workload and outbound to Ariba, S/4, FootPrints and Graph is zero-rated here. | D17: MEDIUM | E17: 25 | F17: =E17-B17 -> 25 | G17: Egress to enterprise APIs flows through NAT or PrivateLink and carries per-GB processing charges. Model it there rather than as zero.
A18: Step Functions Standard | B18: 1.2 | C18: 26,000 workflows at 2 state transitions. The container diagram shows two Step Functions with far more than 2 states each (intake sequencing; validation, investigation, review, write-back, retries, closure). | D18: MEDIUM | E18: 12 | F18: =E18-B18 -> 10.8 | G18: Re-model at 10-15 state transitions per workflow across both state machines.
A19: Amazon Textract | B19: 91 | C19: $91 per 10,000 pages is $9.10 per 1,000, which does not match a single published API rate cleanly. 10,000 pages/month against 27,000 cases implies few cases have attachments, which is unlikely for invoice disputes. | D19: MEDIUM | E19: 150 | F19: =E19-B19 -> 59 | G19: Confirm which API (DetectDocumentText vs AnalyzeDocument Forms/Tables - the rates differ by more than 30x) and re-base the page count on a real attachment rate.
A20: AWS Secrets Manager | B20: 20.08 | C20: 50 secrets is plausible for multi-system credentials. | D20: OK | E20: 20.08 | F20: =E20-B20 -> 0 | G20: No change.
A21: AWS Key Management Service | B21: 16 | C21: 10 CMKs + 2M requests. Arithmetic checks out. | D21: OK | E21: 16 | F21: =E21-B21 -> 0 | G21: No change.
A22: IAM Access Analyzer | B22: 21.6 | C22: Legitimate, but not on the AWS service requirement list (which lists IAM only). | D22: LOW | E22: 21.6 | F22: =E22-B22 -> 0 | G22: Confirm it is in scope for this workload rather than a landing-zone charge.
... A30: Application Load Balancer | B30: 18.38 | C30: One ALB, hourly plus LCU. Reasonable. | D30: OK | E30: 18.38 | F30: =E30-B30 -> 0 | G30: No change.
A31: SUBTOTAL - reviewed lines | B31: =SUM(B4:B30) -> 2722.43 | E31: =SUM(E4:E30) -> 4792.06 | F31: =E31-B31 -> 2069.63
A32: SUBTOTAL excluding model inference (infrastructure only) | B32: =B31-B10 -> 562.43 | C32: Used by the Scenarios sheet, which prices model inference separately so that model choice can be varied without disturbing the infrastructure lines. | E32: =E31-E10 -> 930.43 | F32: =E32-B32 -> 368

Sheet Missing Services
A1: SERVICES ON THE AWS REQUIREMENT LIST THAT ARE ABSENT FROM THE COST ESTIMATE
A3: Service | B3: Req. list ref | C3: Why it is needed here | D3: Monthly $ (indicative) | E3: Confidence | F3: Note
A4: Amazon Bedrock Guardrails | B4: #2 | C4: Mandated 'Yes' for both epics in both architecture versions. Entirely absent from the cost estimate. | D4: ='Consumption Model'!B59 -> 60.642 | E4: HIGH | F4: Links to the Consumption Model boundary-placement figure. Naive placement (screening every agent turn) would cost over 10x this. See Consumption Model section 7 - this is a design decision, not just a line item.
A5: Amazon ECS Cluster + Fargate (MCP + custom orchestrator) | B5: #4, #5, #6 | C5: Arch V1 runs the MCP server and a custom orchestrator on Fargate. The cost estimate instead prices the AgentCore managed path. Both are marked 'Yes' in the requirement list. | D5: 150 | E5: CONDITIONAL | F5: STRUCTURAL CONFLICT. The two documents describe two different architectures. If AgentCore Runtime + Gateway is the chosen path, remove ECS from the requirement list. If both run, both must be priced.
A6: Amazon ECR | B6: #7 | C6: Container image storage for the ECS/Fargate path. | D6: 5 | E6: CONDITIONAL | F6: Conditional on the same decision as above.
A7: GuardDuty Malware Protection for S3 | B7: #14 | C7: FR6 makes attachment scanning mandatory before any extracted content is used. The container diagram shows a scan event between the landing and clean prefixes. | D7: 39 | E7: HIGH | F7: Billed per GB scanned plus per 1,000 objects. Not optional - it is a stated functional requirement.
A8: AWS PrivateLink interface VPC endpoints | B8: #27 | C8: The architecture specifies VPC endpoints and controlled egress. Interface endpoints bill hourly per AZ plus per-GB data processing. | D8: 263 | E8: HIGH | F8: Roughly 12 endpoints x 3 AZs. This is larger than all but two lines in the current estimate and is missing entirely. S3 gateway endpoints (#28) are free and correctly need no line.
A9: Amazon GuardDuty | B9: #24 | C9: Threat detection across CloudTrail, VPC and DNS. | D9: 80 | E9: MEDIUM | F9: May be centrally funded at Boeing. Flag as an allocation question rather than assuming either way.
A10: AWS Security Hub | B10: #23 | C10: Posture management and findings aggregation. | D10: 50 | E10: MEDIUM | F10: As above.
A11: AWS Config | B11: #22 | C11: Configuration recording and compliance rules. | D11: 35 | E11: MEDIUM | F11: As above.
A12: Amazon Inspector | B12: #25 | C12: Vulnerability scanning for container images and Lambda. | D12: 30 | E12: MEDIUM | F12: As above.
A13: AWS WAF | B13: #19 | C13: Protection in front of the load balancer. | D13: 20 | E13: MEDIUM | F13: As above.
A14: AWS X-Ray | B14: #20 | C14: Distributed tracing across Lambda, Step Functions and agent calls. | D14: 15 | E14: MEDIUM | F14: Partially overlaps AgentCore telemetry - confirm there is no double instrumentation.
A15: VPC Flow Logs | B15: #30 | C15: Network flow logging into CloudWatch or S3. | D15: 30 | E15: MEDIUM | F15: Ingestion cost lands in CloudWatch, which is already understated.
A16: Amazon SES | B16: #31 | C16: Listed 'Yes', but the Stage 2-8 design sends through the Outlook group mailbox via Graph. | D16: 3 | E16: LOW | F16: Reconcile: if all outbound email is the Outlook draft-and-reply path (FR3, FR14), SES may not be needed at all. Another inconsistency between the two documents.
A17: Amazon EC2 | B17: #34 | C17: Arch V2 substitutes EC2 for Fargate. | D17: 0 | E17: CONDITIONAL | F17: Only if Arch V2 is selected. Mutually exclusive with the Fargate line above.
A18: SUBTOTAL - missing services | D18: =SUM(D4:D17) -> 780.642
A19: SUBTOTAL excluding Bedrock Guardrails | C19: Used by the Scenarios sheet, which prices Guardrails separately so the placement decision can be varied. | D19: =D18-D4 -> 720
A21: Indicative figures are order-of-magnitude placeholders for services with no usage configuration available. They exist to show that the omission is material, not to serve as a quote. Each needs sizing in the AWS Pricing Calculator against real telemetry, log and scanning volumes.

Sheet Scenarios
A1: SCENARIO RANGE - model choice, guardrail placement and caching dominate everything else
A3: Component | B3: LOW (lean) | C3: BASE (recommended) | D3: HIGH (current assumptions, corrected volume) | E3: Driver
A4: Model inference | B4: ='Consumption Model'!B51*0.35 -> 2002.203 | C4: ='Consumption Model'!B53 -> 3861.63 | D4: ='Consumption Model'!B49 -> 9676.8 | E4: LOW assumes Haiku for both agents with aggressive prompt caching. BASE is Haiku classification + Sonnet investigation with caching on the fixed prefix. HIGH is Opus for everything with no caching. This single choice moves the total by ~10x.
A5: Bedrock Guardrails | B5: ='Consumption Model'!B59*0.5 -> 30.321 | C5: ='Consumption Model'!B59 -> 60.642 | D5: ='Consumption Model'!B58 -> 952.506 | E5: Boundary placement (inbound email + outbound draft) versus screening every agent turn. A pure design decision with a 10-20x cost consequence and no impact on the control it provides at the supplier boundary.
A6: Reviewed infrastructure lines (corrected) | B6: ='Line Review'!E32*0.85 -> 790.8655 | C6: ='Line Review'!E32 -> 930.43 | D6: ='Line Review'!E32*1.25 -> 1163.0375 | E6: From the Line Review sheet. HIGH assumes 5 NAT gateways as currently configured, larger Aurora and full CloudWatch log retention.
A7: Missing services | B7: ='Missing Services'!D19*0.3 -> 216 | C7: ='Missing Services'!D19 -> 720 | D7: ='Missing Services'!D19*1.3 -> 936 | E7: LOW assumes the security baseline (GuardDuty, Security Hub, Config, Inspector, WAF) is centrally funded by Boeing and the ECS/Fargate path is dropped in favour of AgentCore.
A8: TOTAL MONTHLY | B8: =SUM(B4:B7) -> 3039.3895 | C8: =SUM(C4:C7) -> 5572.702 | D8: =SUM(D4:D7) -> 12728.344
A9: TOTAL 12 MONTHS | B9: =B8*12 -> 36472.674 | C9: =C8*12 -> 66872.424 | D9: =D8*12 -> 152740.12
A11: Current estimate, 12 months | B11: 32669.16 | C11: 32669.16 | D11: 32669.16 | E11: As submitted.
A12: Understatement factor | B12: =B9/B11 -> 1.1164252 | C12: =C9/C11 -> 2.0469588 | D12: =D9/D11 -> 4.6753612 | E12: Even the LOW scenario is not far below the submitted figure, and the BASE and HIGH cases are multiples of it.

Sheet Open Questions
A1: OPEN QUESTIONS THAT MUST BE ANSWERED BEFORE THIS ESTIMATE IS DEFENSIBLE
A3: # | B3: Question | C3: Why it matters / what it moves
A4: 1 | B4: What is the actual monthly volume of inbound supplier payment emails, and of FootPrints PO-mismatch tickets? | C4: Every line in both sheets scales from this. Nothing in the requirements, the scenario tabs or the architecture states it. Without it the estimate is a shape, not a number.
A5: 2 | B5: AgentCore managed path, or ECS/Fargate with a custom orchestrator? | C5: The cost estimate prices one, the service list prices the other, and both are marked 'Yes'. This changes the compute model, the container registry requirement, the load balancer requirement and the operational model.
A6: 3 | B6: Which Claude model for each agent? | C6: The estimate silently assumes Opus 4.8 for everything. Splitting Haiku for classification and Sonnet for investigation is the largest single saving available, and nothing in the requirements argues against it.
A7: 4 | B7: Where are Bedrock Guardrails applied - every agent turn, or the supplier boundary only? | C7: A 10-20x cost difference on a line that is currently absent altogether. Boundary placement screens what a supplier sends in and what the system sends out, which is where the risk actually sits.
A8: 5 | B8: Is prompt caching enabled on the system prompt and tool schemas? | C8: The 5,000-token fixed prefix is resent on every one of roughly nine turns per session. Caching it at ~10% of the input rate is the highest-value optimisation in the design and requires no functional change.
A9: 6 | B9: Does each investigation subject get its own agent session, or does one session handle all invoices in an email? | C9: The Stage 4 fan-out point. A session-per-subject model multiplies every AgentCore and model line by the average invoice count per email. The current estimate has no fan-out factor at all.
A10: 7 | B10: How many NAT gateways, in how many AZs, and how much egress to Ariba, S/4, FootPrints and Graph? | C10: Currently five gateways priced at zero, plus zero-rated outbound data transfer. Both are wrong and they compound.
A11: 8 | B11: Are GuardDuty, Security Hub, Config, Inspector and WAF charged to this workload or to a central Boeing security account? | C11: Roughly $215/month of difference, and it is an allocation question rather than a technical one. Worth asking early so the number is not disputed late.
A12: 9 | B12: Which Textract API, and what is the real attachment rate per case? | C12: DetectDocumentText and AnalyzeDocument Forms differ by more than 30x per page. The current $9.10 per 1,000 pages does not match either cleanly.
A13: 10 | B13: What is the evidence retention period for the Aurora case store and the S3 audit prefix? | C13: FR2 and FR30 require the full evidence chain per case. At this volume, retention length drives Aurora storage, backup and S3 growth across the 12-month view - none of which is currently modelled as a curve.
A14: 11 | B14: Is there a non-production environment? | C14: The estimate prices a single environment. DEV and TEST are normally 30-60% of production for this kind of stack, and the Stage 1-9 design assumes a CI/CD path across environments.
